Workbook

Sheet Portada
A1: 1. ANTECEDENTES DE LA EMPRESA | F1: N° de Puestos | G1: Evaluados | H1: Pendientes
A2: Razón Social | B2: PLANTA FAENADORA LO MIRANDA | C2: RUT Empresa | D2: 78.408.440-K | F2: =COUNTIF(Datos!B:B,"Procesos") -> 0 | G2: =COUNTIF(Datos!T:T,"SI") -> 115 | H2: =COUNTIF(Datos!T:T,"NO") -> 0
A3: Actividad Económica | B3: Explotación de mataderos de aves y de otros tipos de animales n.c.p. | C3: Código CIIU
A4: Dirección | B4: Carretera H-30 3814 | C4: Comuna | D4: Doñihue
A5: Nombre Representante Legal | B5: Maximiliano Nuñez
A6: Organismo administrador al que está adherido | B6: INSTITUTO SALUD DEL TRABAJADOR | C6: Fecha inicio | D6: 45402
A7: 2.- CENTRO DE TRABAJO O LUGAR DE TRABAJO
A8: Nombre del centro de trabajo | B8: Planta Lo Miranda | C8: Nº de trabajadores centro de trabajo
A9: Dirección | B9: Carretera H-30 3814 | C9: Hombres
A10: Comuna | B10: Doñihue | C10: Mujeres
A11: 3.- RESPONSABLE IMPLEMENTACIÓN PROTOCOLO
A12: Nombre responsable | B12: MARIANELA TORREALBA GUERRA | C12: Teléfono | D12: 722312747
A13: Cargo | B13: SUPERVISORA DE ACTIVIDADES ERGONOMICAS
A14: Correo electrónico | B14: mtorrealbag@agrosuper.com

Sheet Datos
A1: N° | B1: Área de trabajo | C1: Puesto de trabajo | D1: Tareas del puesto de trabajo | E1: Descripción de la tarea | F1: Horario de funcionamiento | G1: Horas extras POR DIA | H1: Horas extras POR SEMANA | I1: N° Trabajadores Expuestos HOMBRE | J1: N° Trabajadores Expuestos MUJER | K1: Tipo de contrato | L1: Tipo de remuneración | M1: Duración (min) | N1: Pausas de Trabajo | O1: Rotación de tarea | P1: Equipos y Herramienta | Q1: Características de los ambientes y espacios de trabajo (Espacios, barreras arquitectónicas, flujo de tránsito) | R1: Características y disposición espacial del puesto de trabajo (Ubicación de los elementos de trabajo, disposición física del espacio de trabajo) | S1: Características y herramientas utilizadas (Descripción de equipos, herramientas utilizadas, herramientas vibrantes, uso de EPP) | T1: Evaluacion SI/NO
A2: 1 | B2: Congelado | C2: Operador sala de cajas | D2: Armado de cajas (tapa Vetado) | E2: Colaborador posicionado frente al meson con ambas manos toma caja desarmada, para plegar y manipular cartón, armando la caja | F2: Am 07:40 a 15:30 Pm 18:10 a 03:30 | G2: 1 | H2: 6 | I2: 11 | J2: 5 | K2: Indefinido | L2: Fija | M2: 484 | N2: 85 min | O2: SI | P2: NO | Q2: Espacio reducido | R2: Meson Frente a colaborador cajas al costado | S2: Slack, Guantes, casco, zapatos | T2: SI
A3: 2 | B3: Congelado | C3: Operador sala de cajas | D3: Armado de cajas (fondo Vetado) | E3: Colaborador posicionado frente al meson toma caja desarmada y la arma con ambas manos | F3: Am 07:40 a 15:30 Pm 18:10 a 03:31 | G3: 1 | H3: 6 | I3: 11 | J3: 5 | K3: Indefinido | L3: Fija | M3: 484 | N3: 85 min | O3: SI | P3: NO | Q3: Espacio reducido | R3: Meson Frente a colaborador cajas al costado | S3: Slack, Guantes, casco, zapatos | T3: SI
A4: 3 | B4: Congelado | C4: Operador sala de cajas | D4: Armado de cajas (Tapa Mloin) | E4: Colaborador posicionado frente al meson con ambas manos toma caja desarmada, para plegar y manipular cartón, armando la caja | F4: Am 07:40 a 15:30 Pm 18:10 a 03:32 | G4: 1 | H4: 6 | I4: 11 | J4: 5 | K4: Indefinido | L4: Fija | M4: 484 | N4: 85 min | O4: SI | P4: NO | Q4: Espacio reducido | R4: Meson Frente a colaborador cajas al costado | S4: Slack, Guantes, casco, zapatos | T4: SI
A5: 4 | B5: Congelado | C5: Operador sala de cajas | D5: Armado de cajas (Fondo Mloin) | E5: Colaborador posicionado frente al meson con ambas manos toma caja desarmada, para plegar y manipular cartón, armando la caja | F5: Am 07:40 a 15:30 Pm 18:10 a 03:33 | G5: 1 | H5: 6 | I5: 11 | J5: 5 | K5: Indefinido | L5: Fija | M5: 484 | N5: 85 min | O5: SI | P5: NO | Q5: Espacio reducido | R5: Meson Frente a colaborador cajas al costado | S5: Slack, Guantes, casco, zapatos | T5: SI
A6: 5 | B6: Congelado | C6: Operador sala de cajas | D6: Armado de Cajas Tapa Panceta | E6: Colaborador posicionado frente al meson con ambas manos toma caja desarmada, para plegar y manipular cartón, armando la caja | F6: Am 07:40 a 15:30 Pm 18:10 a 03:34 | G6: 1 | H6: 6 | I6: 11 | J6: 5 | K6: Indefinido | L6: Fija | M6: 484 | N6: 85 min | O6: SI | P6: NO | Q6: Espacio reducido | R6: Meson Frente a colaborador cajas al costado | S6: Slack, Guantes, casco, zapatos | T6: SI
A7: 6 | B7: Congelado | C7: Operador sala de cajas | D7: Armado Caja Fondo Panceta | E7: Colaborador posicionado frente al meson con ambas manos toma caja desarmada, para plegar y manipular cartón, armando la caja | F7: Am 07:40 a 15:30 Pm 18:10 a 03:35 | G7: 1 | H7: 6 | I7: 11 | J7: 5 | K7: Indefinido | L7: Fija | M7: 484 | N7: 85 min | O7: SI | P7: NO | Q7: Espacio reducido | R7: Meson Frente a colaborador cajas al costado | S7: Slack, Guantes, casco, zapatos | T7: SI
A8: 7 | B8: Congelado | C8: Operador sala de cajas | D8: Armado de cajas (Tapa Filete) | E8: Colaborador posicionado frente al meson con ambas manos toma caja desarmada, para plegar y manipular cartón, armando la caja | F8: Am 07:40 a 15:30 Pm 18:10 a 03:36 | G8: 1 | H8: 6 | I8: 11 | J8: 5 | K8: Indefinido | L8: Fija | M8: 484 | N8: 85 min | O8: SI | P8: NO | Q8: Espacio reducido | R8: Meson Frente a colaborador cajas al costado | S8: Slack, Guantes, casco, zapatos | T8: SI
A9: 8 | B9: Congelado | C9: Operador sala de cajas | D9: Armado de cajas (Fondo Filete) | E9: Colaborador posicionado frente al meson con ambas manos toma caja desarmada, para plegar y manipular cartón, armando la caja | F9: Am 07:40 a 15:30 Pm 18:10 a 03:37 | G9: 1 | H9: 6 | I9: 11 | J9: 5 | K9: Indefinido | L9: Fija | M9: 484 | N9: 85 min | O9: SI | P9: NO | Q9: Espacio reducido | R9: Meson Frente a colaborador cajas al costado | S9: Slack, Guantes, casco, zapatos | T9: SI
A10: 9 | B10: Congelado | C10: Operador sala de cajas | D10: Armado de cajas (Fondo Filete) | E10: Colaborador posicionado frente al meson con ambas manos toma caja desarmada, para plegar y manipular cartón, armando la caja | F10: Am 07:40 a 15:30 Pm 18:10 a 03:38 | G10: 1 | H10: 6 | I10: 11 | J10: 5 | K10: Indefinido | L10: Fija | M10: 484 | N10: 85 min | O10: SI | P10: NO | Q10: Espacio reducido | R10: Meson Frente a colaborador cajas al costado | S10: Slack, Guantes, casco, zapatos | T10: SI
A11: 10 | B11: Congelado | C11: Operador sala de cajas | D11: Recibir Fondos y tapas | E11: Colaborador recibe caja armada desde maquina, las apila y las ordena en la sala | F11: Am 07:40 a 15:30 Pm 18:10 a 03:39 | G11: 1 | H11: 6 | I11: 11 | J11: 5 | K11: Indefinido | L11: Fija | M11: 484 | N11: 85 min | O11: SI | P11: NO | Q11: Espacio reducido | R11: Meson Frente a colaborador cajas al costado | S11: Slack, Guantes, casco, zapatos | T11: SI
A12: 11 | B12: Congelado | C12: Operador sala de cajas | D12: Colgar Fondos y Tapas | E12: Colaborador toma caja desde meson y cuelga en cinta aerea | F12: Am 07:40 a 15:30 Pm 18:10 a 03:40 | G12: 1 | H12: 6 | I12: 11 | J12: 5 | K12: Indefinido | L12: Fija | M12: 484 | N12: 85 min | O12: SI | P12: NO | Q12: Espacio reducido | R12: Meson Frente a colaborador cajas al costado | S12: Slack, Guantes, casco, zapatos | T12: SI
A13: 12 | B13: Congelado | C13: Operador sala Congelado | D13: Calibrar | E13: Colabortador toma la bandejas con producto que viene desde la cinta frente a el, posiciona la bandeja en estructura volteador, voltea producto con bolsa con ambas manos a caja que se encuentra en meson, pesa producto, luego cierra bolsa y con ambas manos empuja caja para evacuar a la cinta. | F13: Am 07:40 a 15:30 Pm 18:10 a 03:30 | G13: 1 | H13: 6 | I13: 24 | J13: 0 | K13: Indefinido | L13: Fija | M13: 484 | N13: 85 min | O13: SI | P13: NO | Q13: Sin obstáculos físicos o estructurales que limiten al colaborador. No hay circulación de personas y objetos en el espacio de trabajo. | R13: Espacio de trabajo frente a colaborador, cajas en la cinta que pasa por debajo del meson de trabajo y bandejas frente al colaborador | S13: Slack, Guantes, casco, botas | T13: SI
... A16: 15 | B16: Congelado | C16: Operador sala Congelado | D16: Etiquetar | E16: Colaborador pone etiqueta en caja que va sobre la cinta en movimiento | F16: Am 07:40 a 15:30 Pm 18:10 a 03:30 | G16: 1 | H16: 6 | I16: 8 | J16: 0 | K16: Indefinido | L16: Fija | M16: 484 | N16: 85 min | O16: SI | P16: NO | Q16: Sin obstáculos físicos o estructurales que limiten al colaborador. No hay circulación de personas y objetos en el espacio de trabajo. | R16: Espacio de trabjo frente al colaborador | S16: Slack, Guantes, casco, botas | T16: SI
A17: 16 | B17: Congelado | C17: Operador sala Congelado | D17: Direccionar Producto (Mal Enviado) | E17: Colaboradopr toma bandeja que va sobre la cinta y la direcciona de acuerdo al producto | F17: Am 07:40 a 15:30 Pm 18:10 a 03:30 | G17: 1 | H17: 6 | I17: 2 | J17: 0 | K17: Indefinido | L17: Fija | M17: 484 | N17: 85 min | O17: SI | P17: NO | Q17: Sin obstáculos físicos o estructurales que limiten al colaborador. No hay circulación de personas y objetos en el espacio de trabajo. | S17: Slack, Guantes, casco, botas | T17: SI
A18: 17 | B18: Congelado | C18: Operador sala Congelado | D18: Voltear Producto (Volteador) | E18: Colaborador presiona botonera de volteador para sacar producto del bins y alimentar la línera de embalado | F18: Am 07:40 a 15:30 Pm 18:10 a 03:30 | G18: 1 | H18: 6 | I18: 2 | J18: 0 | K18: Indefinido | L18: Fija | M18: 484 | N18: 85 min | O18: SI | P18: NO | Q18: Sin obstáculos físicos o estructurales que limiten al colaborador. No hay circulación de personas y objetos en el espacio de trabajo. | S18: Slack, Guantes, casco, botas | T18: SI
A19: 18 | B19: Congelado | C19: Operador sala Congelado | D19: Embalar Vetado | E19: Colaborador toma producto que va en la cinta en movimiento frente al él y la deposita en caja que se encuentra sobre el mesón, cierra la bolsa y la empuja a la cinta de evacuación que se encuntra al frente | F19: Am 07:40 a 15:30 Pm 18:10 a 03:30 | G19: 1 | H19: 6 | I19: 0 | J19: 12 | K19: Indefinido | L19: Fija | M19: 484 | N19: 85 min | O19: SI | P19: NO | Q19: Sin obstáculos físicos o estructurales que limiten al colaborador. No hay circulación de personas y objetos en el espacio de trabajo. | R19: Meson Frente a colaborador cajas al costado | S19: Slack, Guantes, casco, botas | T19: SI
A20: 19 | B20: Congelado | C20: Operador sala Congelado | D20: Embalar Panceta | E20: Colaborador toma producto que va en la cinta en movimiento frente al él y la deposita en caja que se encuentra sobre el mesón, cierra la bolsa y la empuja a la cinta de evacuación que se encuntra al frente | F20: Am 07:40 a 15:30 Pm 18:10 a 03:30 | G20: 1 | H20: 6 | I20: 0 | J20: 12 | K20: Indefinido | L20: Fija | M20: 484 | N20: 85 min | O20: SI | P20: NO | Q20: Sin obstáculos físicos o estructurales que limiten al colaborador. No hay circulación de personas y objetos en el espacio de trabajo. | S20: Slack, Guantes, casco, botas | T20: SI
A21: 20 | B21: Congelado | C21: Operador sala Congelado | D21: Embalar Filete | E21: Colaborador toma producto que va en la cinta en movimiento frente al él y la deposita en caja que se encuentra sobre el mesón, cierra la bolsa y la empuja a la cinta de evacuación que se encuntra al frente | F21: Am 07:40 a 15:30 Pm 18:10 a 03:30 | G21: 1 | H21: 6 | I21: 0 | J21: 12 | K21: Indefinido | L21: Fija | M21: 484 | N21: 85 min | O21: SI | P21: NO | Q21: Sin obstáculos físicos o estructurales que limiten al colaborador. No hay circulación de personas y objetos en el espacio de trabajo. | S21: Slack, Guantes, casco, botas | T21: SI
A22: 21 | B22: Congelado | C22: Operador sala Congelado | D22: Embalar Mloin | E22: Colaborador toma producto que va en la cinta en movimiento frente al él y la deposita en caja que se encuentra sobre el mesón, cierra la bolsa y la empuja a la cinta de evacuación que se encuntra al frente | F22: Am 07:40 a 15:30 Pm 18:10 a 03:30 | G22: 1 | H22: 6 | I22: 0 | J22: 12 | K22: Indefinido | L22: Fija | M22: 484 | N22: 85 min | O22: SI | P22: NO | Q22: Sin obstáculos físicos o estructurales que limiten al colaborador. No hay circulación de personas y objetos en el espacio de trabajo. | S22: Slack, Guantes, casco, botas | T22: SI
A23: 22 | B23: Congelado | C23: Operador sala Congelado | D23: Tapar Caja | E23: Colaborador Toma caja desde Línea aerea y tapa caja que va por cinta | F23: Am 07:40 a 15:30 Pm 18:10 a 03:30 | G23: 1 | H23: 6 | I23: 0 | J23: 4 | K23: Indefinido | L23: Fija | M23: 484 | N23: 85 min | O23: SI | P23: NO | Q23: Sin obstáculos físicos o estructurales que limiten al colaborador. No hay circulación de personas y objetos en el espacio de trabajo. | R23: Meson Frente a colaborador cajas al costado | S23: Slack, Guantes, casco, botas | T23: SI
A24: 23 | B24: Congelado | C24: Operador sala Congelado | D24: Despalletizar | E24: Colaborador toma caja desde pallet y deposita caja en otro pallet de acuerdo al tipo de producto o pedido | G24: 1 | H24: 6 | I24: 48 | J24: 0 | K24: Indefinido | L24: Fija | M24: 484 | N24: 85 min | O24: SI | P24: NO | Q24: Sin obstáculos físicos o estructurales que limiten al colaborador. No hay circulación de personas y objetos en el espacio de trabajo. | R24: Puesto de trabajo frente al colaborador | S24: Slack, Guantes, casco, botas | T24: SI
A25: 24 | B25: Congelado | C25: Operador sala Congelado | D25: Traspaleta | E25: Colaborador manipula la transpaleta para llevar pedido a ascensor | G25: 1 | H25: 6 | I25: 48 | J25: 0 | K25: Indefinido | L25: Fija | M25: 484 | N25: 85 min | O25: SI | P25: NO | Q25: Sin obstáculos físicos o estructurales que limiten al colaborador. No hay circulación de personas y objetos en el espacio de trabajo. | R25: Puesto de trabajo frente al colaborador | S25: Slack, Guantes, casco, botas | T25: SI
A26: 25 | B26: Desposte | C26: Operador de linea plancha | D26: Abastecer Maja | E26: Colaboradora toma producto de la cinta principal y la ubica en la Maja | F26: 06:30 14:50 / 17:30 a 02:50 | G26: 1 | H26: 6 | I26: 24 | J26: 3 | K26: Indefinido | L26: Fija | M26: 484 | N26: 85 min | O26: SI | P26: NO | Q26: Sin obstáculos físicos o estructurales que limiten al colaborador. No hay circulación de personas y objetos en el espacio de trabajo. | R26: Puesto de trabajo frente al colaborador | S26: Slack, Guantes, casco, botas | T26: SI
A27: 26 | B27: Desposte | C27: Operador de linea plancha | D27: Embalar Cuero | E27: Colaborador selecciona cuero y lo embala | F27: 06:30 14:50 / 17:30 a 02:50 | G27: 1 | H27: 6 | I27: 24 | J27: 3 | K27: Indefinido | L27: Fija | M27: 484 | N27: 85 min | O27: SI | P27: NO | Q27: Sin obstáculos físicos o estructurales que limiten al colaborador. No hay circulación de personas y objetos en el espacio de trabajo. | R27: Puesto de trabajo frente al colaborador | S27: Slack, Guantes, casco, botas | T27: SI
A28: 27 | B28: Desposte | C28: Operador de linea plancha | D28: Operador wizard | E28: Colaborador prolija producto con cuchillo circular wizard | F28: 06:30 14:50 / 17:30 a 02:50 | G28: 1 | H28: 6 | I28: 24 | J28: 3 | K28: Indefinido | L28: Fija | M28: 484 | N28: 85 min | O28: SI | P28: SI | Q28: Sin obstáculos físicos o estructurales que limiten al colaborador. No hay circulación de personas y objetos en el espacio de trabajo. | R28: Puesto de trabajo frente al colaborador | S28: Slack, Guantes, casco, botas | T28: SI
A29: 28 | B29: Desposte | C29: Operador de linea plancha | D29: Sacar Cartilago | E29: Colaborador retira cartilago con cuchillo manual | F29: 06:30 14:50 / 17:30 a 02:50 | G29: 1 | H29: 6 | I29: 24 | J29: 3 | K29: Indefinido | L29: Fija | M29: 484 | N29: 85 min | O29: SI | P29: NO | Q29: Sin obstáculos físicos o estructurales que limiten al colaborador. No hay circulación de personas y objetos en el espacio de trabajo. | R29: Puesto de trabajo frente al colaborador | S29: Slack, Guantes, casco, botas | T29: SI
A30: 29 | B30: Desposte | C30: Operador de linea plancha | D30: Prolijado Lomo tocino | E30: Colaborador saca grasa del producto con cuchillo | F30: 06:30 14:50 / 17:30 a 02:50 | G30: 1 | H30: 6 | I30: 24 | J30: 3 | K30: Indefinido | L30: Fija | M30: 484 | N30: 85 min | O30: SI | P30: NO | Q30: Sin obstáculos físicos o estructurales que limiten al colaborador. No hay circulación de personas y objetos en el espacio de trabajo. | R30: Puesto de trabajo frente al colaborador | S30: Slack, Guantes, casco, botas | T30: SI
A31: 30 | B31: Desposte | C31: Operador de linea plancha | D31: Seleccionador Cuero | E31: Colaborador Selecciona cuero y lo embala | F31: 06:30 14:50 / 17:30 a 02:50 | G31: 1 | H31: 6 | I31: 24 | J31: 3 | K31: Indefinido | L31: Fija | M31: 484 | N31: 85 min | O31: SI | P31: NO | Q31: Sin obstáculos físicos o estructurales que limiten al colaborador. No hay circulación de personas y objetos en el espacio de trabajo. | R31: Puesto de trabajo frente al colaborador | S31: Slack, Guantes, casco, botas | T31: SI
A32: 31 | B32: Desposte | C32: Operador de linea plancha | D32: Despunte Plancha | E32: Colaborador corta punta de plancha para cuadrar | F32: 06:30 14:50 / 17:30 a 02:50 | G32: 1 | H32: 6 | I32: 24 | J32: 3 | K32: Indefinido | L32: Fija | M32: 484 | N32: 85 min | O32: SI | P32: NO | Q32: Sin obstáculos físicos o estructurales que limiten al colaborador. No hay circulación de personas y objetos en el espacio de trabajo. | R32: Puesto de trabajo frente al colaborador | S32: Slack, Guantes, casco, botas | T32: SI
A33: 32 | B33: Desposte | C33: Operador de linea plancha | D33: Prolijado de Malaya | E33: Coilaborador saca grasa de la malaya con whizard | F33: 06:30 14:50 / 17:30 a 02:50 | G33: 1 | H33: 6 | I33: 24 | J33: 3 | K33: Indefinido | L33: Fija | M33: 484 | N33: 85 min | O33: SI | P33: SI | Q33: Sin obstáculos físicos o estructurales que limiten al colaborador. No hay circulación de personas y objetos en el espacio de trabajo. | R33: Puesto de trabajo frente al colaborador | S33: Slack, Guantes, casco, botas | T33: SI
A34: 33 | B34: Desposte | C34: Operador de linea plancha | D34: Calibrado Plancha | E34: Colaborador pesa producto para darle peso requerido | F34: 06:30 14:50 / 17:30 a 02:50 | G34: 1 | H34: 6 | I34: 24 | J34: 3 | K34: Indefinido | L34: Fija | M34: 484 | N34: 85 min | O34: SI | P34: NO | Q34: Sin obstáculos físicos o estructurales que limiten al colaborador. No hay circulación de personas y objetos en el espacio de trabajo. | R34: Puesto de trabajo frente al colaborador | S34: Slack, Guantes, casco, botas | T34: SI
A35: 34 | B35: Desposte | C35: Operador Línea Embolsado | D35: Embolsado Panceta | E35: Colaborador Toma la panceta desde la cinta y envuelve con plástico | F35: 06:30 14:50 / 17:30 a 02:50 | G35: 1 | H35: 6 | I35: 0 | J35: 50 | K35: Indefinido | L35: Fija | M35: 484 | N35: 85 min | O35: SI | P35: NO | Q35: Sin obstáculos físicos o estructurales que limiten al colaborador. No hay circulación de personas y objetos en el espacio de trabajo. | R35: Puesto de trabajo frente al colaborador | S35: Slack, Guantes, casco, botas | T35: SI
A36: 35 | B36: Desposte | C36: Operador Línea Embolsado | D36: Embolsado Lomo | E36: Colaborador Toma el lomo desde la cinta, mide con cintga y envuelve con plástico | F36: 06:30 14:50 / 17:30 a 02:50 | G36: 1 | H36: 6 | I36: 0 | J36: 50 | K36: Indefinido | L36: Fija | M36: 484 | N36: 85 min | O36: SI | P36: NO | Q36: Sin obstáculos físicos o estructurales que limiten al colaborador. No hay circulación de personas y objetos en el espacio de trabajo. | R36: Puesto de trabajo frente al colaborador | S36: Slack, Guantes, casco, botas | T36: SI
A37: 36 | B37: Desposte | C37: Operador Línea Embolsado | D37: Embolsado Vetados | E37: Colaborador Toma el lomo desde la cinta, lo pesa y envuelve con plástico | F37: 06:30 14:50 / 17:30 a 02:50 | G37: 1 | H37: 6 | I37: 0 | J37: 50 | K37: Indefinido | L37: Fija | M37: 484 | N37: 85 min | O37: SI | P37: NO | Q37: Sin obstáculos físicos o estructurales que limiten al colaborador. No hay circulación de personas y objetos en el espacio de trabajo. | R37: Puesto de trabajo frente al colaborador | S37: Slack, Guantes, casco, botas | T37: SI
... A59: 58 | B59: Desposte | C59: Operador Línea Costillar | D59: Cuadrar panceta | E59: Colaborador toma producto desde linea y abastece maquina para cuadar panceta | F59: 06:30 14:50 / 17:30 a 02:50 | G59: 1 | H59: 6 | I59: 38 | J59: 0 | K59: Indefinido | L59: Fija | M59: 484 | N59: 85 min | O59: SI | P59: NO | Q59: Sin obstáculos físicos o estructurales que limiten al colaborador. No hay circulación de personas y objetos en el espacio de trabajo. | R59: Puesto de trabajo frente al colaborador | S59: Slack, Guantes, casco, botas | T59: SI
A60: 59 | B60: Desposte | C60: Operador Línea Costillar | D60: Despunte Producto | F60: 06:30 14:50 / 17:30 a 02:50 | G60: 1 | H60: 6 | I60: 38 | J60: 0 | K60: Indefinido | L60: Fija | M60: 484 | N60: 85 min | O60: SI | P60: NO | Q60: Sin obstáculos físicos o estructurales que limiten al colaborador. No hay circulación de personas y objetos en el espacio de trabajo. | R60: Puesto de trabajo frente al colaborador | S60: Slack, Guantes, casco, botas | T60: SI
A61: 60 | B61: Desposte | C61: Operador Línea Costillar | D61: Prolijado Whizard (grasa) | E61: Colaborador extrae grada del producto con cuchillo whizard | F61: 06:30 14:50 / 17:30 a 02:50 | G61: 1 | H61: 6 | I61: 38 | J61: 0 | K61: Indefinido | L61: Fija | M61: 484 | N61: 85 min | O61: SI | P61: SI | Q61: Sin obstáculos físicos o estructurales que limiten al colaborador. No hay circulación de personas y objetos en el espacio de trabajo. | R61: Puesto de trabajo frente al colaborador | S61: Slack, Guantes, casco, botas | T61: SI
A62: 61 | B62: Desposte | C62: Operador Línea Costillar | D62: Calibrado | E62: Colaborador toma producto de cinta lo posicioa en pesa y calibra con cuchillo | F62: 06:30 14:50 / 17:30 a 02:50 | G62: 1 | H62: 6 | I62: 38 | J62: 0 | K62: Indefinido | L62: Fija | M62: 484 | N62: 85 min | O62: SI | P62: SI | Q62: Sin obstáculos físicos o estructurales que limiten al colaborador. No hay circulación de personas y objetos en el espacio de trabajo. | R62: Puesto de trabajo frente al colaborador | S62: Slack, Guantes, casco, botas | T62: SI
A63: 62 | B63: Desposte | C63: Operador Línea Costillar | D63: Cortado de Costillar | E63: Colaborador toma costilla de cinta y abastece maquina para cortarla | F63: 06:30 14:50 / 17:30 a 02:50 | G63: 1 | H63: 6 | I63: 38 | J63: 0 | K63: Indefinido | L63: Fija | M63: 484 | N63: 85 min | O63: SI | P63: NO | Q63: Sin obstáculos físicos o estructurales que limiten al colaborador. No hay circulación de personas y objetos en el espacio de trabajo. | R63: Puesto de trabajo frente al colaborador | S63: Slack, Guantes, casco, botas | T63: SI
...

Sheet Inicial
A1: N° | C1: Puesto de trabajo | D1: Tareas del puesto de trabajo | E1: Horario de funcionamiento | F1: Horas extras POR DIA | G1: Horas extras POR SEMANA | H1: N° Trabajadores Expuestos HOMBRE | I1: N° Trabajadores Expuestos MUJER | J1: Trabajo repetitivo de miembros superiores. | K1: Postura de trabajo estática | L1: MMC Levantamiento/Descenso | M1: MMC Empuje/Arrastre | N1: Manejo manual de pacientes / personas | O1: Vibración de cuerpo completo | P1: Vibración segmento mano – brazo | Q1: Resultado identificación inicial
B2: Area | J2: ¿Existe una o más tareas donde utilice las manos y miembros superiores con una duración total de una hora o más durante la jornada laboral y con un tiempo total de 5 o más horas a la semana? Donde tenga que movilizar, levantar, empujar, encajar, sostener, posicionar, armar, limpiar, apretar, lanzar, cortar, presionar, desarmar, atornillar, desatornillar, digitar con presión, comprimir, ubicar, moldear, traccionar. | K2: ¿Existen posturas de trabajo estáticas de cabeza/cuello, tronco y/o miembros superiores e inferiores, mantenidas por más de 4 segundos consecutivamente? Donde se observe estar sentado, cabeza inclinada hacia adelante o atrás, mirada situada en planos bajo nivel medio de tórax o pecho, cabeza rotada permanentemente hacia algún lado, mirada situada en planos sobre el nivel de cabeza, hombros situados por delante de las caderas de manera continua, tronco rotado o inclinado para sostener o movilizar objetos. | L2: Para el Levantamiento/Descenso/Transporte: ¿Existe levantamiento, descenso o transporte manual de un objeto de 3kg o más? Se observa que levanta, sostiene, trasporta, desplaza, moviliza, ubica con precisión ordenando, empuja, arrastra o tracciona, apila, paletiza. | M2: Tracción/Empuje ¿Existe empuje o arrastre de una carga utilizando el cuerpo completo con 1 o 2 manos? Se observa el empuje y/o arrastre de diferentes maneras carros, plataformas con rueda, superficies deslizantes, detención de objetos en movimiento, camillas, camas, sillas de rueda, paletizadores, grúas de uso manual mecanizadas, formas de tracción y empuje hechizas, carretillas. No se considera empuje y arrastre carros motorizados y controlados manualmente (conducción) | N2: ¿Se realiza alguna actividad que requiere fuerza para empujar, tirar, levantar, descender, transferir o de alguna manera mover o sostener una persona o parte del cuerpo de una persona? *NOTA: La condición a identificar debe incluir la actividad de manipulación, ya sea que se realice con o sin dispositivos de asistencia. Esta condición está determinada por el riesgo asociado a las características de la carga humana que requiere control sensible de la masa corporal por parte del operador. | O2: ¿Están los trabajadores/as expuestos/as a vibraciones por una fuente de vibración de cuerpo entero perceptible por el trabajador/a? Se presenta en cercanía de máquinas donde se percibe la vibración, superficies vibrantes donde se está de pie o sentado como en maquinaria pesada y de conducción sentados o de pie. | P2: ¿Están los trabajadores/as en contacto con una fuente de vibración del segmento mano - brazo? Y ¿esta condición es frecuente o inherente a la tarea realizada?. Se presenta en situaciones de manejo de herramientas neumáticas o eléctricas, atornilladores o destornilladores neumáticos o eléctricos, uso de herramientas con impacto como martillos, cinceles, herramientas percutoras como taladros o grandes percutores
A3: =Datos!A2 -> 1 | B3: =Datos!B2 -> Congelado | C3: =Datos!C2 -> Operador sala de cajas | D3: =Datos!D2 -> Armado de cajas (tapa Vetado) | E3: =Datos!F2 -> Am 07:40 a 15:30 Pm 18:10 a 03:30 | F3: =Datos!G2 -> 1 | G3: =Datos!H2 -> 6 | H3: =Datos!I2 -> 11 | I3: =Datos!J2 -> 5 | J3: SI | K3: NO | L3: NO | M3: NO | N3: NO | O3: NO | P3: NO | Q3: =IF(AND(J3="NO",K3="NO",L3="NO",M3="NO",N3="NO",O3="NO",P3="NO"),"Ausencia total del riesgo, reevaluar cada 3 años con nueva identificación inicial","Aplicar identificación avanzada-condición aceptable para cada tipo de factor de riesgo identificado") -> Aplicar identificación avanzada-condición aceptable para cada tipo de factor de riesgo identificado
A4: =Datos!A3 -> 2 | B4: =Datos!B3 -> Congelado | C4: =Datos!C3 -> Operador sala de cajas | D4: =Datos!D3 -> Armado de cajas (fondo Vetado) | E4: =Datos!F3 -> Am 07:40 a 15:30 Pm 18:10 a 03:31 | F4: =Datos!G3 -> 1 | G4: =Datos!H3 -> 6 | H4: =Datos!I3 -> 11 | I4: =Datos!J3 -> 5 | J4: SI | K4: NO | L4: NO | M4: NO | N4: NO | O4: NO | P4: NO | Q4: =IF(AND(J4="NO",K4="NO",L4="NO",M4="NO",N4="NO",O4="NO",P4="NO"),"Ausencia total del riesgo, reevaluar cada 3 años con nueva identificación inicial","Aplicar identificación avanzada-condición aceptable para cada tipo de factor de riesgo identificado") -> Aplicar identificación avanzada-condición aceptable para cada tipo de factor de riesgo identificado
A5: =Datos!A4 -> 3 | B5: =Datos!B4 -> Congelado | C5: =Datos!C4 -> Operador sala de cajas | D5: =Datos!D4 -> Armado de cajas (Tapa Mloin) | E5: =Datos!F4 -> Am 07:40 a 15:30 Pm 18:10 a 03:32 | F5: =Datos!G4 -> 1 | G5: =Datos!H4 -> 6 | H5: =Datos!I4 -> 11 | I5: =Datos!J4 -> 5 | J5: SI | K5: NO | L5: NO | M5: NO | N5: NO | O5: NO | P5: NO | Q5: =IF(AND(J5="NO",K5="NO",L5="NO",M5="NO",N5="NO",O5="NO",P5="NO"),"Ausencia total del riesgo, reevaluar cada 3 años con nueva identificación inicial","Aplicar identificación avanzada-condición aceptable para cada tipo de factor de riesgo identificado") -> Aplicar identificación avanzada-condición aceptable para cada tipo de factor de riesgo identificado
A6: =Datos!A5 -> 4 | B6: =Datos!B5 -> Congelado | C6: =Datos!C5 -> Operador sala de cajas | D6: =Datos!D5 -> Armado de cajas (Fondo Mloin) | E6: =Datos!F5 -> Am 07:40 a 15:30 Pm 18:10 a 03:33 | F6: =Datos!G5 -> 1 | G6: =Datos!H5 -> 6 | H6: =Datos!I5 -> 11 | I6: =Datos!J5 -> 5 | J6: SI | K6: NO | L6: NO | M6: NO | N6: NO | O6: NO | P6: NO | Q6: =IF(AND(J6="NO",K6="NO",L6="NO",M6="NO",N6="NO",O6="NO",P6="NO"),"Ausencia total del riesgo, reevaluar cada 3 años con nueva identificación inicial","Aplicar identificación avanzada-condición aceptable para cada tipo de factor de riesgo identificado") -> Aplicar identificación avanzada-condición aceptable para cada tipo de factor de riesgo identificado
A7: =Datos!A6 -> 5 | B7: =Datos!B6 -> Congelado | C7: =Datos!C6 -> Operador sala de cajas | D7: =Datos!D6 -> Armado de Cajas Tapa Panceta | E7: =Datos!F6 -> Am 07:40 a 15:30 Pm 18:10 a 03:34 | F7: =Datos!G6 -> 1 | G7: =Datos!H6 -> 6 | H7: =Datos!I6 -> 11 | I7: =Datos!J6 -> 5 | J7: SI | K7: NO | L7: NO | M7: NO | N7: NO | O7: NO | P7: NO | Q7: =IF(AND(J7="NO",K7="NO",L7="NO",M7="NO",N7="NO",O7="NO",P7="NO"),"Ausencia total del riesgo, reevaluar cada 3 años con nueva identificación inicial","Aplicar identificación avanzada-condición aceptable para cada tipo de factor de riesgo identificado") -> Aplicar identificación avanzada-condición aceptable para cada tipo de factor de riesgo identificado
A8: =Datos!A7 -> 6 | B8: =Datos!B7 -> Congelado | C8: =Datos!C7 -> Operador sala de cajas | D8: =Datos!D7 -> Armado Caja Fondo Panceta | E8: =Datos!F7 -> Am 07:40 a 15:30 Pm 18:10 a 03:35 | F8: =Datos!G7 -> 1 | G8: =Datos!H7 -> 6 | H8: =Datos!I7 -> 11 | I8: =Datos!J7 -> 5 | J8: SI | K8: NO | L8: NO | M8: NO | N8: NO | O8: NO | P8: NO | Q8: =IF(AND(J8="NO",K8="NO",L8="NO",M8="NO",N8="NO",O8="NO",P8="NO"),"Ausencia total del riesgo, reevaluar cada 3 años con nueva identificación inicial","Aplicar identificación avanzada-condición aceptable para cada tipo de factor de riesgo identificado") -> Aplicar identificación avanzada-condición aceptable para cada tipo de factor de riesgo identificado
A9: =Datos!A8 -> 7 | B9: =Datos!B8 -> Congelado | C9: =Datos!C8 -> Operador sala de cajas | D9: =Datos!D8 -> Armado de cajas (Tapa Filete) | E9: =Datos!F8 -> Am 07:40 a 15:30 Pm 18:10 a 03:36 | F9: =Datos!G8 -> 1 | G9: =Datos!H8 -> 6 | H9: =Datos!I8 -> 11 | I9: =Datos!J8 -> 5 | J9: SI | K9: NO | L9: NO | M9: NO | N9: NO | O9: NO | P9: NO | Q9: =IF(AND(J9="NO",K9="NO",L9="NO",M9="NO",N9="NO",O9="NO",P9="NO"),"Ausencia total del riesgo, reevaluar cada 3 años con nueva identificación inicial","Aplicar identificación avanzada-condición aceptable para cada tipo de factor de riesgo identificado") -> Aplicar identificación avanzada-condición aceptable para cada tipo de factor de riesgo identificado
A10: =Datos!A9 -> 8 | B10: =Datos!B9 -> Congelado | C10: =Datos!C9 -> Operador sala de cajas | D10: =Datos!D9 -> Armado de cajas (Fondo Filete) | E10: =Datos!F9 -> Am 07:40 a 15:30 Pm 18:10 a 03:37 | F10: =Datos!G9 -> 1 | G10: =Datos!H9 -> 6 | H10: =Datos!I9 -> 11 | I10: =Datos!J9 -> 5 | J10: SI | K10: NO | L10: NO | M10: NO | N10: NO | O10: NO | P10: NO | Q10: =IF(AND(J10="NO",K10="NO",L10="NO",M10="NO",N10="NO",O10="NO",P10="NO"),"Ausencia total del riesgo, reevaluar cada 3 años con nueva identificación inicial","Aplicar identificación avanzada-condición aceptable para cada tipo de factor de riesgo identificado") -> Aplicar identificación avanzada-condición aceptable para cada tipo de factor de riesgo identificado
A11: =Datos!A10 -> 9 | B11: =Datos!B10 -> Congelado | C11: =Datos!C10 -> Operador sala de cajas | D11: =Datos!D10 -> Armado de cajas (Fondo Filete) | E11: =Datos!F10 -> Am 07:40 a 15:30 Pm 18:10 a 03:38 | F11: =Datos!G10 -> 1 | G11: =Datos!H10 -> 6 | H11: =Datos!I10 -> 11 | I11: =Datos!J10 -> 5 | J11: SI | K11: NO | L11: NO | M11: NO | N11: NO | O11: NO | P11: NO | Q11: =IF(AND(J11="NO",K11="NO",L11="NO",M11="NO",N11="NO",O11="NO",P11="NO"),"Ausencia total del riesgo, reevaluar cada 3 años con nueva identificación inicial","Aplicar identificación avanzada-condición aceptable para cada tipo de factor de riesgo identificado") -> Aplicar identificación avanzada-condición aceptable para cada tipo de factor de riesgo identificado
A12: =Datos!A11 -> 10 | B12: =Datos!B11 -> Congelado | C12: =Datos!C11 -> Operador sala de cajas | D12: =Datos!D11 -> Recibir Fondos y tapas | E12: =Datos!F11 -> Am 07:40 a 15:30 Pm 18:10 a 03:39 | F12: =Datos!G11 -> 1 | G12: =Datos!H11 -> 6 | H12: =Datos!I11 -> 11 | I12: =Datos!J11 -> 5 | J12: SI | K12: NO | L12: NO | M12: NO | N12: NO | O12: NO | P12: NO | Q12: =IF(AND(J12="NO",K12="NO",L12="NO",M12="NO",N12="NO",O12="NO",P12="NO"),"Ausencia total del riesgo, reevaluar cada 3 años con nueva identificación inicial","Aplicar identificación avanzada-condición aceptable para cada tipo de factor de riesgo identificado") -> Aplicar identificación avanzada-condición aceptable para cada tipo de factor de riesgo identificado
A13: =Datos!A12 -> 11 | B13: =Datos!B12 -> Congelado | C13: =Datos!C12 -> Operador sala de cajas | D13: =Datos!D12 -> Colgar Fondos y Tapas | E13: =Datos!F12 -> Am 07:40 a 15:30 Pm 18:10 a 03:40 | F13: =Datos!G12 -> 1 | G13: =Datos!H12 -> 6 | H13: =Datos!I12 -> 11 | I13: =Datos!J12 -> 5 | J13: SI | K13: NO | L13: NO | M13: NO | N13: NO | O13: NO | P13: NO | Q13: =IF(AND(J13="NO",K13="NO",L13="NO",M13="NO",N13="NO",O13="NO",P13="NO"),"Ausencia total del riesgo, reevaluar cada 3 años con nueva identificación inicial","Aplicar identificación avanzada-condición aceptable para cada tipo de factor de riesgo identificado") -> Aplicar identificación avanzada-condición aceptable para cada tipo de factor de riesgo identificado
A14: =Datos!A13 -> 12 | B14: =Datos!B13 -> Congelado | C14: =Datos!C13 -> Operador sala Congelado | D14: =Datos!D13 -> Calibrar | E14: =Datos!F13 -> Am 07:40 a 15:30 Pm 18:10 a 03:30 | F14: =Datos!G13 -> 1 | G14: =Datos!H13 -> 6 | H14: =Datos!I13 -> 24 | I14: =Datos!J13 -> 0 | J14: SI | K14: NO | L14: NO | M14: NO | N14: NO | O14: NO | P14: NO | Q14: =IF(AND(J14="NO",K14="NO",L14="NO",M14="NO",N14="NO",O14="NO",P14="NO"),"Ausencia total del riesgo, reevaluar cada 3 años con nueva identificación inicial","Aplicar identificación avanzada-condición aceptable para cada tipo de factor de riesgo identificado") -> Aplicar identificación avanzada-condición aceptable para cada tipo de factor de riesgo identificado
... A117: =Datos!A116 -> 115 | B117: =Datos!B116 -> Desposte | C117: =Datos!C116 -> Operador Línea Filete y Cabeza | D117: =Datos!D116 -> Embalaje patas y manos | E117: =Datos!F116 -> 06:30 14:50 / 17:30 a 02:50 | F117: =Datos!G116 -> 1 | G117: =Datos!H116 -> 6 | H117: =Datos!I116 -> 20 | I117: =Datos!J116 -> 6 | J117: SI | K117: NO | L117: SI | M117: NO | N117: NO | O117: NO | P117: NO | Q117: =IF(AND(J117="NO",K117="NO",L117="NO",M117="NO",N117="NO",O117="NO",P117="NO"),"Ausencia total del riesgo, reevaluar cada 3 años con nueva identificación inicial","Aplicar identificación avanzada-condición aceptable para cada tipo de factor de riesgo identificado") -> Aplicar identificación avanzada-condición aceptable para cada tipo de factor de riesgo identificado
A118: =Datos!A117 -> 0 | B118: =Datos!B117 -> 0 | C118: =Datos!C117 -> 0 | D118: =Datos!D117 -> 0 | E118: =Datos!F117 -> 0 | F118: =Datos!G117 -> 0 | G118: =Datos!H117 -> 0 | H118: =Datos!I117 -> 0 | I118: =Datos!J117 -> 0 | Q118: =IF(AND(J118="NO",K118="NO",L118="NO",M118="NO",N118="NO",O118="NO",P118="NO"),"Ausencia total del riesgo, reevaluar cada 3 años con nueva identificación inicial","Aplicar identificación avanzada-condición aceptable para cada tipo de factor de riesgo identificado") -> Aplicar identificación avanzada-condición aceptable para cada tipo de factor de riesgo identificado
A119: =Datos!A118 -> 0 | B119: =Datos!B118 -> 0 | C119: =Datos!C118 -> 0 | D119: =Datos!D118 -> 0 | E119: =Datos!F118 -> 0 | F119: =Datos!G118 -> 0 | G119: =Datos!H118 -> 0 | H119: =Datos!I118 -> 0 | I119: =Datos!J118 -> 0 | Q119: =IF(AND(J119="NO",K119="NO",L119="NO",M119="NO",N119="NO",O119="NO",P119="NO"),"Ausencia total del riesgo, reevaluar cada 3 años con nueva identificación inicial","Aplicar identificación avanzada-condición aceptable para cada tipo de factor de riesgo identificado") -> Aplicar identificación avanzada-condición aceptable para cada tipo de factor de riesgo identificado
A120: =Datos!A119 -> 0 | B120: =Datos!B119 -> 0 | C120: =Datos!C119 -> 0 | D120: =Datos!D119 -> 0 | E120: =Datos!F119 -> 0 | F120: =Datos!G119 -> 0 | G120: =Datos!H119 -> 0 | H120: =Datos!I119 -> 0 | I120: =Datos!J119 -> 0 | Q120: =IF(AND(J120="NO",K120="NO",L120="NO",M120="NO",N120="NO",O120="NO",P120="NO"),"Ausencia total del riesgo, reevaluar cada 3 años con nueva identificación inicial","Aplicar identificación avanzada-condición aceptable para cada tipo de factor de riesgo identificado") -> Aplicar identificación avanzada-condición aceptable para cada tipo de factor de riesgo identificado
A121: =Datos!A120 -> 0 | B121: =Datos!B120 -> 0 | C121: =Datos!C120 -> 0 | D121: =Datos!D120 -> 0 | E121: =Datos!F120 -> 0 | F121: =Datos!G120 -> 0 | G121: =Datos!H120 -> 0 | H121: =Datos!I120 -> 0 | I121: =Datos!J120 -> 0 | Q121: =IF(AND(J121="NO",K121="NO",L121="NO",M121="NO",N121="NO",O121="NO",P121="NO"),"Ausencia total del riesgo, reevaluar cada 3 años con nueva identificación inicial","Aplicar identificación avanzada-condición aceptable para cada tipo de factor de riesgo identificado") -> Aplicar identificación avanzada-condición aceptable para cada tipo de factor de riesgo identificado
A122: =Datos!A121 -> 0 | B122: =Datos!B121 -> 0 | C122: =Datos!C121 -> 0 | D122: =Datos!D121 -> 0 | E122: =Datos!F121 -> 0 | F122: =Datos!G121 -> 0 | G122: =Datos!H121 -> 0 | H122: =Datos!I121 -> 0 | I122: =Datos!J121 -> 0 | Q122: =IF(AND(J122="NO",K122="NO",L122="NO",M122="NO",N122="NO",O122="NO",P122="NO"),"Ausencia total del riesgo, reevaluar cada 3 años con nueva identificación inicial","Aplicar identificación avanzada-condición aceptable para cada tipo de factor de riesgo identificado") -> Aplicar identificación avanzada-condición aceptable para cada tipo de factor de riesgo identificado
A123: =Datos!A122 -> 0 | B123: =Datos!B122 -> 0 | C123: =Datos!C122 -> 0 | D123: =Datos!D122 -> 0 | E123: =Datos!F122 -> 0 | F123: =Datos!G122 -> 0 | G123: =Datos!H122 -> 0 | H123: =Datos!I122 -> 0 | I123: =Datos!J122 -> 0 | Q123: =IF(AND(J123="NO",K123="NO",L123="NO",M123="NO",N123="NO",O123="NO",P123="NO"),"Ausencia total del riesgo, reevaluar cada 3 años con nueva identificación inicial","Aplicar identificación avanzada-condición aceptable para cada tipo de factor de riesgo identificado") -> Aplicar identificación avanzada-condición aceptable para cada tipo de factor de riesgo identificado
A124: =Datos!A124 -> 0 | B124: =Datos!B124 -> 0 | C124: =Datos!C124 -> 0 | D124: =Datos!D124 -> 0 | E124: 06:30 14:50/17:30 a 02:82 | F124: =Datos!G124 -> 0 | G124: 38 | H124: =Datos!I124 -> 0 | I124: =Datos!J124 -> 0 | Q124: =IF(AND(J124="NO",K124="NO",L124="NO",M124="NO",N124="NO",O124="NO",P124="NO"),"Ausencia total del riesgo, reevaluar cada 3 años con nueva identificación inicial","Aplicar identificación avanzada-condición aceptable para cada tipo de factor de riesgo identificado") -> Aplicar identificación avanzada-condición aceptable para cada tipo de factor de riesgo identificado
A125: =Datos!A125 -> 0 | B125: =Datos!B125 -> 0 | C125: =Datos!C125 -> 0 | D125: =Datos!D125 -> 0 | E125: 06:30 14:50/17:30 a 02:83 | F125: =Datos!G125 -> 0 | G125: 39 | H125: =Datos!I125 -> 0 | I125: =Datos!J125 -> 0 | Q125: =IF(AND(J125="NO",K125="NO",L125="NO",M125="NO",N125="NO",O125="NO",P125="NO"),"Ausencia total del riesgo, reevaluar cada 3 años con nueva identificación inicial","Aplicar identificación avanzada-condición aceptable para cada tipo de factor de riesgo identificado") -> Aplicar identificación avanzada-condición aceptable para cada tipo de factor de riesgo identificado
A126: =Datos!A126 -> 0 | B126: =Datos!B126 -> 0 | C126: =Datos!C126 -> 0 | D126: =Datos!D126 -> 0 | E126: 06:30 14:50/17:30 a 02:84 | F126: =Datos!G126 -> 0 | G126: 40 | H126: =Datos!I126 -> 0 | I126: =Datos!J126 -> 0 | Q126: =IF(AND(J126="NO",K126="NO",L126="NO",M126="NO",N126="NO",O126="NO",P126="NO"),"Ausencia total del riesgo, reevaluar cada 3 años con nueva identificación inicial","Aplicar identificación avanzada-condición aceptable para cada tipo de factor de riesgo identificado") -> Aplicar identificación avanzada-condición aceptable para cada tipo de factor de riesgo identificado
A127: =Datos!A127 -> 0 | B127: =Datos!B127 -> 0 | C127: =Datos!C127 -> 0 | D127: =Datos!D127 -> 0 | E127: 06:30 14:50/17:30 a 02:85 | F127: =Datos!G127 -> 0 | G127: 41 | H127: =Datos!I127 -> 0 | I127: =Datos!J127 -> 0 | Q127: =IF(AND(J127="NO",K127="NO",L127="NO",M127="NO",N127="NO",O127="NO",P127="NO"),"Ausencia total del riesgo, reevaluar cada 3 años con nueva identificación inicial","Aplicar identificación avanzada-condición aceptable para cada tipo de factor de riesgo identificado") -> Aplicar identificación avanzada-condición aceptable para cada tipo de factor de riesgo identificado
A128: =Datos!A128 -> 0 | B128: =Datos!B128 -> 0 | C128: =Datos!C128 -> 0 | D128: =Datos!D128 -> 0 | E128: 06:30 14:50/17:30 a 02:86 | F128: =Datos!G128 -> 0 | G128: 42 | H128: =Datos!I128 -> 0 | I128: =Datos!J128 -> 0 | Q128: =IF(AND(J128="NO",K128="NO",L128="NO",M128="NO",N128="NO",O128="NO",P128="NO"),"Ausencia total del riesgo, reevaluar cada 3 años con nueva identificación inicial","Aplicar identificación avanzada-condición aceptable para cada tipo de factor de riesgo identificado") -> Aplicar identificación avanzada-condición aceptable para cada tipo de factor de riesgo identificado
A129: =Datos!A129 -> 0 | B129: =Datos!B129 -> 0 | C129: =Datos!C129 -> 0 | D129: =Datos!D129 -> 0 | E129: 06:30 14:50/17:30 a 02:87 | F129: =Datos!G129 -> 0 | G129: 43 | H129: =Datos!I129 -> 0 | I129: =Datos!J129 -> 0 | Q129: =IF(AND(J129="NO",K129="NO",L129="NO",M129="NO",N129="NO",O129="NO",P129="NO"),"Ausencia total del riesgo, reevaluar cada 3 años con nueva identificación inicial","Aplicar identificación avanzada-condición aceptable para cada tipo de factor de riesgo identificado") -> Aplicar identificación avanzada-condición aceptable para cada tipo de factor de riesgo identificado
A130: =Datos!A130 -> 0 | B130: =Datos!B130 -> 0 | C130: =Datos!C130 -> 0 | D130: =Datos!D130 -> 0 | E130: 06:30 14:50/17:30 a 02:88 | F130: =Datos!G130 -> 0 | G130: 44 | H130: =Datos!I130 -> 0 | I130: =Datos!J130 -> 0 | Q130: =IF(AND(J130="NO",K130="NO",L130="NO",M130="NO",N130="NO",O130="NO",P130="NO"),"Ausencia total del riesgo, reevaluar cada 3 años con nueva identificación inicial","Aplicar identificación avanzada-condición aceptable para cada tipo de factor de riesgo identificado") -> Aplicar identificación avanzada-condición aceptable para cada tipo de factor de riesgo identificado
A131: =Datos!A131 -> 0 | B131: =Datos!B131 -> 0 | C131: =Datos!C131 -> 0 | D131: =Datos!D131 -> 0 | E131: 06:30 14:50/17:30 a 02:89 | F131: =Datos!G131 -> 0 | G131: 45 | H131: =Datos!I131 -> 0 | I131: =Datos!J131 -> 0 | Q131: =IF(AND(J131="NO",K131="NO",L131="NO",M131="NO",N131="NO",O131="NO",P131="NO"),"Ausencia total del riesgo, reevaluar cada 3 años con nueva identificación inicial","Aplicar identificación avanzada-condición aceptable para cada tipo de factor de riesgo identificado") -> Aplicar identificación avanzada-condición aceptable para cada tipo de factor de riesgo identificado
A132: =Datos!A132 -> 0 | B132: =Datos!B132 -> 0 | C132: =Datos!C132 -> 0 | D132: =Datos!D132 -> 0 | E132: 06:30 14:50/17:30 a 02:90 | F132: =Datos!G132 -> 0 | G132: 46 | H132: =Datos!I132 -> 0 | I132: =Datos!J132 -> 0 | Q132: =IF(AND(J132="NO",K132="NO",L132="NO",M132="NO",N132="NO",O132="NO",P132="NO"),"Ausencia total del riesgo, reevaluar cada 3 años con nueva identificación inicial","Aplicar identificación avanzada-condición aceptable para cada tipo de factor de riesgo identificado") -> Aplicar identificación avanzada-condición aceptable para cada tipo de factor de riesgo identificado
A133: =Datos!A133 -> 0 | B133: =Datos!B133 -> 0 | C133: =Datos!C133 -> 0 | D133: =Datos!D133 -> 0 | E133: 06:30 14:50/17:30 a 02:91 | F133: =Datos!G133 -> 0 | G133: 47 | H133: =Datos!I133 -> 0 | I133: =Datos!J133 -> 0 | Q133: =IF(AND(J133="NO",K133="NO",L133="NO",M133="NO",N133="NO",O133="NO",P133="NO"),"Ausencia total del riesgo, reevaluar cada 3 años con nueva identificación inicial","Aplicar identificación avanzada-condición aceptable para cada tipo de factor de riesgo identificado") -> Aplicar identificación avanzada-condición aceptable para cada tipo de factor de riesgo identificado
A134: =Datos!A134 -> 0 | B134: =Datos!B134 -> 0 | C134: =Datos!C134 -> 0 | D134: =Datos!D134 -> 0 | E134: 06:30 14:50/17:30 a 02:92 | F134: =Datos!G134 -> 0 | G134: 48 | H134: =Datos!I134 -> 0 | I134: =Datos!J134 -> 0 | Q134: =IF(AND(J134="NO",K134="NO",L134="NO",M134="NO",N134="NO",O134="NO",P134="NO"),"Ausencia total del riesgo, reevaluar cada 3 años con nueva identificación inicial","Aplicar identificación avanzada-condición aceptable para cada tipo de factor de riesgo identificado") -> Aplicar identificación avanzada-condición aceptable para cada tipo de factor de riesgo identificado
A135: =Datos!A135 -> 0 | B135: =Datos!B135 -> 0 | C135: =Datos!C135 -> 0 | D135: =Datos!D135 -> 0 | E135: 06:30 14:50/17:30 a 02:93 | F135: =Datos!G135 -> 0 | G135: 49 | H135: =Datos!I135 -> 0 | I135: =Datos!J135 -> 0

Sheet Mov. Rep.
A1: MOVIMIENTO REPETITIVO | F1: Horas extras | H1: N° Trabajadores Expuestos | J1: Tabla II. IDENTIFICACIÓN AVANZADA – Trabajo Repetitivo de Miembros Superiores– Condición Aceptable | Q1: Tabla VI. IDENTIFICACIÓN AVANZADA – Tarea(s) Repetitiva(s) de miembros superiores –– Condición Crítica | X1: Plan de acción
A2: N° | B2: Área de trabajo | C2: Puesto de trabajo | D2: Tareas del puesto de trabajo | E2: Horario de funcionamiento | F2: Por dia | G2: Por Semana | H2: HOMBRE | I2: MUJER | J2: ¿Los miembros superiores trabajan por menos del 50% de la duración total de la tarea repetitiva? | K2: ¿Los codos se mantienen por debajo del nivel de los hombros por al menos el 90% del total de la duración de la(s) tarea(s) repetitiva? | L2: ¿Existe esfuerzo moderado ejercido por el trabajador (Percepción de Esfuerzo máximo 4 según Escala de Borg CR-10) ejercidas por el trabajador por no más de 1 hora mientras dura la(s) tarea(s) repetitiva? | M2: Ausencias de esfuerzo máximo (esfuerzo percibido = 5 o más en la Escala de Borg CR-10) | N2: Presencia de pausas (excluyendo la pausa para almuerzo) que al menos duren 8 minutos cada 2 horas. | O2: ¿Se realiza la tarea repetitiva durante menos de 8 horas al día? | P2: Condición Aceptable | Q2: ¿Las acciones técnicas del miembro superior son tan rápidas que no se pueden contar con una simple observación directa? | R2: Uno o ambos brazos están realizando la tarea con el codo sobre el nivel del hombro por el 50% o más, del tiempo total de trabajo repetitivo | S2: ¿Se utiliza agarre en “pinza" (o todo tipo de tomada usando las puntas de los dedos) por más del 80% de la duración total del trabajo repetitivo? | T2: ¿Se aplica fuerza máxima por el trabajador (esfuerzo percibido = 5 o más en la Escala de Borg CR-10) por 10% o más del tiempo total de la tarea repetitiva? | U2: ¿No hay más de una pausa (Incluyendo el almuerzo) en un turno de 6 a 8 horas? | V2: ¿La duración total de las tareas repetitivas excede 8 horas dentro de un turno? | W2: Condición Crítica | X2: Fecha aplicación identificación avanzada | Y2: Medidas de control (administrativas) | Z2: Medidas de control (Ingeniería) | AA2: Responsable aplicación medida | AB2: Fecha de implementación medidas (Max 90 días) | AC2: Evidencia
A3: =Inicial!A3 -> 1 | B3: =Inicial!B3 -> Congelado | C3: =Inicial!C3 -> Operador sala de cajas | D3: =Inicial!D3 -> Armado de cajas (tapa Vetado) | E3: =IF(Inicial!J3="SI",Inicial!E3,"N/A") -> Am 07:40 a 15:30 Pm 18:10 a 03:30 | F3: =IF(Inicial!J3="SI",Inicial!F3,"N/A") -> 1 | G3: =IF(Inicial!J3="SI",Inicial!G3,"N/A") -> 6 | H3: =IF(Inicial!J3="SI",Inicial!H3,"N/A") -> 11 | I3: =IF(Inicial!J3="SI",Inicial!I3,"N/A") -> 5 | J3: NO | K3: SI | L3: SI | M3: SI | N3: SI | O3: SI | P3: =IF(OR(J3="NO",K3="NO",L3="NO",M3="NO",N3="NO",O3="NO"),"No Aceptable","Aceptable") -> No Aceptable | Q3: NO | R3: NO | S3: NO | T3: NO | U3: NO | V3: NO | W3: =IF(AND(Q3="NO",R3="NO",S3="NO",T3="NO",U3="NO",V3="NO"),"No Critico","Critico") -> No Critico
A4: =Inicial!A4 -> 2 | B4: =Inicial!B4 -> Congelado | C4: =Inicial!C4 -> Operador sala de cajas | D4: =Inicial!D4 -> Armado de cajas (fondo Vetado) | E4: =IF(Inicial!J4="SI",Inicial!E4,"N/A") -> Am 07:40 a 15:30 Pm 18:10 a 03:31 | F4: =IF(Inicial!J4="SI",Inicial!F4,"N/A") -> 1 | G4: =IF(Inicial!J4="SI",Inicial!G4,"N/A") -> 6 | H4: =IF(Inicial!J4="SI",Inicial!H4,"N/A") -> 11 | I4: =IF(Inicial!J4="SI",Inicial!I4,"N/A") -> 5 | J4: NO | K4: SI | L4: SI | M4: SI | N4: SI | O4: SI | P4: =IF(OR(J4="NO",K4="NO",L4="NO",M4="NO",N4="NO",O4="NO"),"No Aceptable","Aceptable") -> No Aceptable | Q4: NO | R4: NO | S4: NO | T4: NO | U4: NO | V4: NO | W4: =IF(AND(Q4="NO",R4="NO",S4="NO",T4="NO",U4="NO",V4="NO"),"No Critico","Critico") -> No Critico
A5: =Inicial!A5 -> 3 | B5: =Inicial!B5 -> Congelado | C5: =Inicial!C5 -> Operador sala de cajas | D5: =Inicial!D5 -> Armado de cajas (Tapa Mloin) | E5: =IF(Inicial!J5="SI",Inicial!E5,"N/A") -> Am 07:40 a 15:30 Pm 18:10 a 03:32 | F5: =IF(Inicial!J5="SI",Inicial!F5,"N/A") -> 1 | G5: =IF(Inicial!J5="SI",Inicial!G5,"N/A") -> 6 | H5: =IF(Inicial!J5="SI",Inicial!H5,"N/A") -> 11 | I5: =IF(Inicial!J5="SI",Inicial!I5,"N/A") -> 5 | J5: NO | K5: SI | L5: SI | M5: SI | N5: SI | O5: SI | P5: =IF(OR(J5="NO",K5="NO",L5="NO",M5="NO",N5="NO",O5="NO"),"No Aceptable","Aceptable") -> No Aceptable | Q5: NO | R5: NO | S5: NO | T5: NO | U5: NO | V5: NO | W5: =IF(AND(Q5="NO",R5="NO",S5="NO",T5="NO",U5="NO",V5="NO"),"No Critico","Critico") -> No Critico
A6: =Inicial!A6 -> 4 | B6: =Inicial!B6 -> Congelado | C6: =Inicial!C6 -> Operador sala de cajas | D6: =Inicial!D6 -> Armado de cajas (Fondo Mloin) | E6: =IF(Inicial!J6="SI",Inicial!E6,"N/A") -> Am 07:40 a 15:30 Pm 18:10 a 03:33 | F6: =IF(Inicial!J6="SI",Inicial!F6,"N/A") -> 1 | G6: =IF(Inicial!J6="SI",Inicial!G6,"N/A") -> 6 | H6: =IF(Inicial!J6="SI",Inicial!H6,"N/A") -> 11 | I6: =IF(Inicial!J6="SI",Inicial!I6,"N/A") -> 5 | J6: NO | K6: SI | L6: SI | M6: SI | N6: SI | O6: SI | P6: =IF(OR(J6="NO",K6="NO",L6="NO",M6="NO",N6="NO",O6="NO"),"No Aceptable","Aceptable") -> No Aceptable | Q6: NO | R6: NO | S6: NO | T6: NO | U6: NO | V6: NO | W6: =IF(AND(Q6="NO",R6="NO",S6="NO",T6="NO",U6="NO",V6="NO"),"No Critico","Critico") -> No Critico
A7: =Inicial!A7 -> 5 | B7: =Inicial!B7 -> Congelado | C7: =Inicial!C7 -> Operador sala de cajas | D7: =Inicial!D7 -> Armado de Cajas Tapa Panceta | E7: =IF(Inicial!J7="SI",Inicial!E7,"N/A") -> Am 07:40 a 15:30 Pm 18:10 a 03:34 | F7: =IF(Inicial!J7="SI",Inicial!F7,"N/A") -> 1 | G7: =IF(Inicial!J7="SI",Inicial!G7,"N/A") -> 6 | H7: =IF(Inicial!J7="SI",Inicial!H7,"N/A") -> 11 | I7: =IF(Inicial!J7="SI",Inicial!I7,"N/A") -> 5 | J7: NO | K7: SI | L7: SI | M7: SI | N7: SI | O7: SI | P7: =IF(OR(J7="NO",K7="NO",L7="NO",M7="NO",N7="NO",O7="NO"),"No Aceptable","Aceptable") -> No Aceptable | Q7: NO | R7: NO | S7: NO | T7: NO | U7: NO | V7: NO | W7: =IF(AND(Q7="NO",R7="NO",S7="NO",T7="NO",U7="NO",V7="NO"),"No Critico","Critico") -> No Critico
A8: =Inicial!A8 -> 6 | B8: =Inicial!B8 -> Congelado | C8: =Inicial!C8 -> Operador sala de cajas | D8: =Inicial!D8 -> Armado Caja Fondo Panceta | E8: =IF(Inicial!J8="SI",Inicial!E8,"N/A") -> Am 07:40 a 15:30 Pm 18:10 a 03:35 | F8: =IF(Inicial!J8="SI",Inicial!F8,"N/A") -> 1 | G8: =IF(Inicial!J8="SI",Inicial!G8,"N/A") -> 6 | H8: =IF(Inicial!J8="SI",Inicial!H8,"N/A") -> 11 | I8: =IF(Inicial!J8="SI",Inicial!I8,"N/A") -> 5 | J8: NO | K8: SI | L8: SI | M8: SI | N8: SI | O8: SI | P8: =IF(OR(J8="NO",K8="NO",L8="NO",M8="NO",N8="NO",O8="NO"),"No Aceptable","Aceptable") -> No Aceptable | Q8: NO | R8: NO | S8: NO | T8: NO | U8: NO | V8: NO | W8: =IF(AND(Q8="NO",R8="NO",S8="NO",T8="NO",U8="NO",V8="NO"),"No Critico","Critico") -> No Critico
A9: =Inicial!A9 -> 7 | B9: =Inicial!B9 -> Congelado | C9: =Inicial!C9 -> Operador sala de cajas | D9: =Inicial!D9 -> Armado de cajas (Tapa Filete) | E9: =IF(Inicial!J9="SI",Inicial!E9,"N/A") -> Am 07:40 a 15:30 Pm 18:10 a 03:36 | F9: =IF(Inicial!J9="SI",Inicial!F9,"N/A") -> 1 | G9: =IF(Inicial!J9="SI",Inicial!G9,"N/A") -> 6 | H9: =IF(Inicial!J9="SI",Inicial!H9,"N/A") -> 11 | I9: =IF(Inicial!J9="SI",Inicial!I9,"N/A") -> 5 | J9: NO | K9: SI | L9: SI | M9: SI | N9: SI | O9: SI | P9: =IF(OR(J9="NO",K9="NO",L9="NO",M9="NO",N9="NO",O9="NO"),"No Aceptable","Aceptable") -> No Aceptable | Q9: NO | R9: NO | S9: NO | T9: NO | U9: NO | V9: NO | W9: =IF(AND(Q9="NO",R9="NO",S9="NO",T9="NO",U9="NO",V9="NO"),"No Critico","Critico") -> No Critico
A10: =Inicial!A10 -> 8 | B10: =Inicial!B10 -> Congelado | C10: =Inicial!C10 -> Operador sala de cajas | D10: =Inicial!D10 -> Armado de cajas (Fondo Filete) | E10: =IF(Inicial!J10="SI",Inicial!E10,"N/A") -> Am 07:40 a 15:30 Pm 18:10 a 03:37 | F10: =IF(Inicial!J10="SI",Inicial!F10,"N/A") -> 1 | G10: =IF(Inicial!J10="SI",Inicial!G10,"N/A") -> 6 | H10: =IF(Inicial!J10="SI",Inicial!H10,"N/A") -> 11 | I10: =IF(Inicial!J10="SI",Inicial!I10,"N/A") -> 5 | J10: NO | K10: SI | L10: SI | M10: SI | N10: SI | O10: SI | P10: =IF(OR(J10="NO",K10="NO",L10="NO",M10="NO",N10="NO",O10="NO"),"No Aceptable","Aceptable") -> No Aceptable | Q10: NO | R10: NO | S10: NO | T10: NO | U10: NO | V10: NO | W10: =IF(AND(Q10="NO",R10="NO",S10="NO",T10="NO",U10="NO",V10="NO"),"No Critico","Critico") -> No Critico
A11: =Inicial!A11 -> 9 | B11: =Inicial!B11 -> Congelado | C11: =Inicial!C11 -> Operador sala de cajas | D11: =Inicial!D11 -> Armado de cajas (Fondo Filete) | E11: =IF(Inicial!J11="SI",Inicial!E11,"N/A") -> Am 07:40 a 15:30 Pm 18:10 a 03:38 | F11: =IF(Inicial!J11="SI",Inicial!F11,"N/A") -> 1 | G11: =IF(Inicial!J11="SI",Inicial!G11,"N/A") -> 6 | H11: =IF(Inicial!J11="SI",Inicial!H11,"N/A") -> 11 | I11: =IF(Inicial!J11="SI",Inicial!I11,"N/A") -> 5 | J11: NO | K11: SI | L11: SI | M11: SI | N11: SI | O11: SI | P11: =IF(OR(J11="NO",K11="NO",L11="NO",M11="NO",N11="NO",O11="NO"),"No Aceptable","Aceptable") -> No Aceptable | Q11: NO | R11: NO | S11: NO | T11: NO | U11: NO | V11: NO | W11: =IF(AND(Q11="NO",R11="NO",S11="NO",T11="NO",U11="NO",V11="NO"),"No Critico","Critico") -> No Critico
A12: =Inicial!A12 -> 10 | B12: =Inicial!B12 -> Congelado | C12: =Inicial!C12 -> Operador sala de cajas | D12: =Inicial!D12 -> Recibir Fondos y tapas | E12: =IF(Inicial!J12="SI",Inicial!E12,"N/A") -> Am 07:40 a 15:30 Pm 18:10 a 03:39 | F12: =IF(Inicial!J12="SI",Inicial!F12,"N/A") -> 1 | G12: =IF(Inicial!J12="SI",Inicial!G12,"N/A") -> 6 | H12: =IF(Inicial!J12="SI",Inicial!H12,"N/A") -> 11 | I12: =IF(Inicial!J12="SI",Inicial!I12,"N/A") -> 5 | J12: NO | K12: SI | L12: SI | M12: SI | N12: SI | O12: SI | P12: =IF(OR(J12="NO",K12="NO",L12="NO",M12="NO",N12="NO",O12="NO"),"No Aceptable","Aceptable") -> No Aceptable | Q12: NO | R12: NO | S12: NO | T12: NO | U12: NO | V12: NO | W12: =IF(AND(Q12="NO",R12="NO",S12="NO",T12="NO",U12="NO",V12="NO"),"No Critico","Critico") -> No Critico
A13: =Inicial!A13 -> 11 | B13: =Inicial!B13 -> Congelado | C13: =Inicial!C13 -> Operador sala de cajas | D13: =Inicial!D13 -> Colgar Fondos y Tapas | E13: =IF(Inicial!J13="SI",Inicial!E13,"N/A") -> Am 07:40 a 15:30 Pm 18:10 a 03:40 | F13: =IF(Inicial!J13="SI",Inicial!F13,"N/A") -> 1 | G13: =IF(Inicial!J13="SI",Inicial!G13,"N/A") -> 6 | H13: =IF(Inicial!J13="SI",Inicial!H13,"N/A") -> 11 | I13: =IF(Inicial!J13="SI",Inicial!I13,"N/A") -> 5 | J13: NO | K13: SI | L13: SI | M13: SI | N13: SI | O13: SI | P13: =IF(OR(J13="NO",K13="NO",L13="NO",M13="NO",N13="NO",O13="NO"),"No Aceptable","Aceptable") -> No Aceptable | Q13: NO | R13: NO | S13: NO | T13: NO | U13: NO | V13: NO | W13: =IF(AND(Q13="NO",R13="NO",S13="NO",T13="NO",U13="NO",V13="NO"),"No Critico","Critico") -> No Critico
A14: =Inicial!A14 -> 12 | B14: =Inicial!B14 -> Congelado | C14: =Inicial!C14 -> Operador sala Congelado | D14: =Inicial!D14 -> Calibrar | E14: =IF(Inicial!J14="SI",Inicial!E14,"N/A") -> Am 07:40 a 15:30 Pm 18:10 a 03:30 | F14: =IF(Inicial!J14="SI",Inicial!F14,"N/A") -> 1 | G14: =IF(Inicial!J14="SI",Inicial!G14,"N/A") -> 6 | H14: =IF(Inicial!J14="SI",Inicial!H14,"N/A") -> 24 | I14: =IF(Inicial!J14="SI",Inicial!I14,"N/A") -> 0 | J14: NO | K14: SI | L14: SI | M14: SI | N14: SI | O14: SI | P14: =IF(OR(J14="NO",K14="NO",L14="NO",M14="NO",N14="NO",O14="NO"),"No Aceptable","Aceptable") -> No Aceptable | Q14: NO | R14: NO | S14: NO | T14: NO | U14: NO | V14: NO | W14: =IF(AND(Q14="NO",R14="NO",S14="NO",T14="NO",U14="NO",V14="NO"),"No Critico","Critico") -> No Critico
... A107: =Inicial!A107 -> 105 | B107: =Inicial!B107 -> Desposte | C107: =Inicial!C107 -> Operador Línea Empaque | D107: =Inicial!D107 -> Direccionado | E107: =IF(Inicial!J107="SI",Inicial!E107,"N/A") -> 06:30 14:50 / 17:30 a 02:50 | F107: =IF(Inicial!J107="SI",Inicial!F107,"N/A") -> 1 | G107: =IF(Inicial!J107="SI",Inicial!G107,"N/A") -> 6 | H107: =IF(Inicial!J107="SI",Inicial!H107,"N/A") -> 36 | I107: =IF(Inicial!J107="SI",Inicial!I107,"N/A") -> 8 | J107: NO | K107: SI | L107: SI | M107: SI | N107: SI | O107: SI | P107: =IF(OR(J107="NO",K107="NO",L107="NO",M107="NO",N107="NO",O107="NO"),"No Aceptable","Aceptable") -> No Aceptable | Q107: NO | R107: NO | S107: NO | T107: NO | U107: NO | V107: NO | W107: =IF(AND(Q107="NO",R107="NO",S107="NO",T107="NO",U107="NO",V107="NO"),"No Critico","Critico") -> No Critico
A108: =Inicial!A108 -> 106 | B108: =Inicial!B108 -> Desposte | C108: =Inicial!C108 -> Operador Línea Empaque | D108: =Inicial!D108 -> Embalado | E108: =IF(Inicial!J108="SI",Inicial!E108,"N/A") -> 06:30 14:50 / 17:30 a 02:50 | F108: =IF(Inicial!J108="SI",Inicial!F108,"N/A") -> 1 | G108: =IF(Inicial!J108="SI",Inicial!G108,"N/A") -> 6 | H108: =IF(Inicial!J108="SI",Inicial!H108,"N/A") -> 36 | I108: =IF(Inicial!J108="SI",Inicial!I108,"N/A") -> 8 | P108: =IF(OR(J108="NO",K108="NO",L108="NO",M108="NO",N108="NO",O108="NO"),"No Aceptable","Aceptable") -> Aceptable | W108: =IF(AND(Q108="NO",R108="NO",S108="NO",T108="NO",U108="NO",V108="NO"),"No Critico","Critico") -> Critico
A109: =Inicial!A109 -> 107 | B109: =Inicial!B109 -> Desposte | C109: =Inicial!C109 -> Operador Línea Empaque | D109: =Inicial!D109 -> PC | E109: =IF(Inicial!J109="SI",Inicial!E109,"N/A") -> 06:30 14:50 / 17:30 a 02:50 | F109: =IF(Inicial!J109="SI",Inicial!F109,"N/A") -> 1 | G109: =IF(Inicial!J109="SI",Inicial!G109,"N/A") -> 6 | H109: =IF(Inicial!J109="SI",Inicial!H109,"N/A") -> 36 | I109: =IF(Inicial!J109="SI",Inicial!I109,"N/A") -> 8 | P109: =IF(OR(J109="NO",K109="NO",L109="NO",M109="NO",N109="NO",O109="NO"),"No Aceptable","Aceptable") -> Aceptable | W109: =IF(AND(Q109="NO",R109="NO",S109="NO",T109="NO",U109="NO",V109="NO"),"No Critico","Critico") -> Critico
